2024-08-08 22:05:53,127 - INFO - Creating file: points.json
2024-08-08 22:05:53,131 - INFO - Creating file: masterquiz.json
2024-08-08 22:05:53,142 - DEBUG - Starting new HTTPS connection (1): api.telegram.org:443
2024-08-08 22:05:53,771 - DEBUG - https://api.telegram.org:443 "GET /bot7010440554:AAGTXkaQW1wmYvvj5X2e-agZUvztY09uyng/getMe HTTP/11" 200 251
2024-08-08 22:05:53,784 - DEBUG - Starting new HTTPS connection (1): api.telegram.org:443
2024-08-08 22:05:54,325 - DEBUG - https://api.telegram.org:443 "GET /bot7010440554:AAGTXkaQW1wmYvvj5X2e-agZUvztY09uyng/getUpdates?offset=1&timeout=20 HTTP/11" 200 10093
2024-08-08 22:06:14,522 - DEBUG - https://api.telegram.org:443 "GET /bot7010440554:AAGTXkaQW1wmYvvj5X2e-agZUvztY09uyng/getUpdates?offset=879038060&timeout=20 HTTP/11" 200 23
2024-08-08 22:06:34,821 - DEBUG - https://api.telegram.org:443 "GET /bot7010440554:AAGTXkaQW1wmYvvj5X2e-agZUvztY09uyng/getUpdates?offset=879038060&timeout=20 HTTP/11" 200 23
2024-08-08 22:06:55,394 - DEBUG - https://api.telegram.org:443 "GET /bot7010440554:AAGTXkaQW1wmYvvj5X2e-agZUvztY09uyng/getUpdates?offset=879038060&timeout=20 HTTP/11" 200 23
2024-08-08 22:07:15,584 - DEBUG - https://api.telegram.org:443 "GET /bot7010440554:AAGTXkaQW1wmYvvj5X2e-agZUvztY09uyng/getUpdates?offset=879038060&timeout=20 HTTP/11" 200 23
2024-08-08 22:07:36,675 - DEBUG - https://api.telegram.org:443 "GET /bot7010440554:AAGTXkaQW1wmYvvj5X2e-agZUvztY09uyng/getUpdates?offset=879038060&timeout=20 HTTP/11" 200 23
2024-08-09 11:26:58,752 - DEBUG - Starting new HTTPS connection (1): api.telegram.org:443
2024-08-09 11:26:59,455 - DEBUG - https://api.telegram.org:443 "GET /bot7010440554:AAGTXkaQW1wmYvvj5X2e-agZUvztY09uyng/getMe HTTP/11" 200 251
2024-08-09 11:26:59,463 - DEBUG - Starting new HTTPS connection (1): api.telegram.org:443
2024-08-09 11:27:04,052 - DEBUG - https://api.telegram.org:443 "GET /bot7010440554:AAGTXkaQW1wmYvvj5X2e-agZUvztY09uyng/getUpdates?offset=1&timeout=20 HTTP/11" 409 143
2024-08-09 11:27:04,065 - ERROR - Threaded polling exception: A request to the Telegram API was unsuccessful. Error code: 409. Description: Conflict: terminated by other getUpdates request; make sure that only one bot instance is running
2024-08-09 11:27:04,068 - ERROR - Exception traceback:
Traceback (most recent call last):
  File "/data/data/com.termux/files/usr/lib/python3.11/site-packages/telebot/__init__.py", line 1214, in __threaded_polling
    polling_thread.raise_exceptions()
  File "/data/data/com.termux/files/usr/lib/python3.11/site-packages/telebot/util.py", line 111, in raise_exceptions
    raise self.exception_info
  File "/data/data/com.termux/files/usr/lib/python3.11/site-packages/telebot/util.py", line 93, in run
    task(*args, **kwargs)
  File "/data/data/com.termux/files/usr/lib/python3.11/site-packages/telebot/__init__.py", line 676, in __retrieve_updates
    updates = self.get_updates(offset=(self.last_update_id + 1),
             ^^^^^^^^^^^^^^^^^^^^^^^^^^^^^^^^^^^^^^^^^^^^^^^^^^
  File "/data/data/com.termux/files/usr/lib/python3.11/site-packages/telebot/__init__.py", line 648, in get_updates
    json_updates = apihelper.get_updates(
                   ^^^^^^^^^^^^^^^^^^^^^^
  File "/data/data/com.termux/files/usr/lib/python3.11/site-packages/telebot/apihelper.py", line 330, in get_updates
    return _make_request(token, method_url, params=payload)
           ^^^^^^^^^^^^^^^^^^^^^^^^^^^^^^^^^^^^^^^^^^^^^^^^
  File "/data/data/com.termux/files/usr/lib/python3.11/site-packages/telebot/apihelper.py", line 168, in _make_request
    json_result = _check_result(method_name, result)
                  ^^^^^^^^^^^^^^^^^^^^^^^^^^^^^^^^^^
  File "/data/data/com.termux/files/usr/lib/python3.11/site-packages/telebot/apihelper.py", line 195, in _check_result
    raise ApiTelegramException(method_name, result, result_json)
telebot.apihelper.ApiTelegramException: A request to the Telegram API was unsuccessful. Error code: 409. Description: Conflict: terminated by other getUpdates request; make sure that only one bot instance is running

2024-08-09 11:27:08,203 - DEBUG - https://api.telegram.org:443 "GET /bot7010440554:AAGTXkaQW1wmYvvj5X2e-agZUvztY09uyng/getUpdates?offset=1&timeout=20 HTTP/11" 409 143
2024-08-09 11:27:08,211 - ERROR - Threaded polling exception: A request to the Telegram API was unsuccessful. Error code: 409. Description: Conflict: terminated by other getUpdates request; make sure that only one bot instance is running
2024-08-09 11:27:08,214 - ERROR - Exception traceback:
Traceback (most recent call last):
  File "/data/data/com.termux/files/usr/lib/python3.11/site-packages/telebot/__init__.py", line 1214, in __threaded_polling
    polling_thread.raise_exceptions()
  File "/data/data/com.termux/files/usr/lib/python3.11/site-packages/telebot/util.py", line 111, in raise_exceptions
    raise self.exception_info
  File "/data/data/com.termux/files/usr/lib/python3.11/site-packages/telebot/util.py", line 93, in run
    task(*args, **kwargs)
  File "/data/data/com.termux/files/usr/lib/python3.11/site-packages/telebot/__init__.py", line 676, in __retrieve_updates
    updates = self.get_updates(offset=(self.last_update_id + 1),
             ^^^^^^^^^^^^^^^^^^^^^^^^^^^^^^^^^^^^^^^^^^^^^^^^^^
  File "/data/data/com.termux/files/usr/lib/python3.11/site-packages/telebot/__init__.py", line 648, in get_updates
    json_updates = apihelper.get_updates(
                   ^^^^^^^^^^^^^^^^^^^^^^
  File "/data/data/com.termux/files/usr/lib/python3.11/site-packages/telebot/apihelper.py", line 330, in get_updates
    return _make_request(token, method_url, params=payload)
           ^^^^^^^^^^^^^^^^^^^^^^^^^^^^^^^^^^^^^^^^^^^^^^^^
  File "/data/data/com.termux/files/usr/lib/python3.11/site-packages/telebot/apihelper.py", line 168, in _make_request
    json_result = _check_result(method_name, result)
                  ^^^^^^^^^^^^^^^^^^^^^^^^^^^^^^^^^^
  File "/data/data/com.termux/files/usr/lib/python3.11/site-packages/telebot/apihelper.py", line 195, in _check_result
    raise ApiTelegramException(method_name, result, result_json)
telebot.apihelper.ApiTelegramException: A request to the Telegram API was unsuccessful. Error code: 409. Description: Conflict: terminated by other getUpdates request; make sure that only one bot instance is running

2024-08-09 11:27:13,102 - DEBUG - https://api.telegram.org:443 "GET /bot7010440554:AAGTXkaQW1wmYvvj5X2e-agZUvztY09uyng/getUpdates?offset=1&timeout=20 HTTP/11" 409 143
2024-08-09 11:27:13,124 - ERROR - Threaded polling exception: A request to the Telegram API was unsuccessful. Error code: 409. Description: Conflict: terminated by other getUpdates request; make sure that only one bot instance is running
2024-08-09 11:27:13,135 - ERROR - Exception traceback:
Traceback (most recent call last):
  File "/data/data/com.termux/files/usr/lib/python3.11/site-packages/telebot/__init__.py", line 1214, in __threaded_polling
    polling_thread.raise_exceptions()
  File "/data/data/com.termux/files/usr/lib/python3.11/site-packages/telebot/util.py", line 111, in raise_exceptions
    raise self.exception_info
  File "/data/data/com.termux/files/usr/lib/python3.11/site-packages/telebot/util.py", line 93, in run
    task(*args, **kwargs)
  File "/data/data/com.termux/files/usr/lib/python3.11/site-packages/telebot/__init__.py", line 676, in __retrieve_updates
    updates = self.get_updates(offset=(self.last_update_id + 1),
             ^^^^^^^^^^^^^^^^^^^^^^^^^^^^^^^^^^^^^^^^^^^^^^^^^^
  File "/data/data/com.termux/files/usr/lib/python3.11/site-packages/telebot/__init__.py", line 648, in get_updates
    json_updates = apihelper.get_updates(
                   ^^^^^^^^^^^^^^^^^^^^^^
  File "/data/data/com.termux/files/usr/lib/python3.11/site-packages/telebot/apihelper.py", line 330, in get_updates
    return _make_request(token, method_url, params=payload)
           ^^^^^^^^^^^^^^^^^^^^^^^^^^^^^^^^^^^^^^^^^^^^^^^^
  File "/data/data/com.termux/files/usr/lib/python3.11/site-packages/telebot/apihelper.py", line 168, in _make_request
    json_result = _check_result(method_name, result)
                  ^^^^^^^^^^^^^^^^^^^^^^^^^^^^^^^^^^
  File "/data/data/com.termux/files/usr/lib/python3.11/site-packages/telebot/apihelper.py", line 195, in _check_result
    raise ApiTelegramException(method_name, result, result_json)
telebot.apihelper.ApiTelegramException: A request to the Telegram API was unsuccessful. Error code: 409. Description: Conflict: terminated by other getUpdates request; make sure that only one bot instance is running

2024-08-09 11:27:19,544 - DEBUG - https://api.telegram.org:443 "GET /bot7010440554:AAGTXkaQW1wmYvvj5X2e-agZUvztY09uyng/getUpdates?offset=1&timeout=20 HTTP/11" 409 143
2024-08-09 11:27:19,546 - ERROR - Threaded polling exception: A request to the Telegram API was unsuccessful. Error code: 409. Description: Conflict: terminated by other getUpdates request; make sure that only one bot instance is running
2024-08-09 11:27:19,548 - ERROR - Exception traceback:
Traceback (most recent call last):
  File "/data/data/com.termux/files/usr/lib/python3.11/site-packages/telebot/__init__.py", line 1214, in __threaded_polling
    polling_thread.raise_exceptions()
  File "/data/data/com.termux/files/usr/lib/python3.11/site-packages/telebot/util.py", line 111, in raise_exceptions
    raise self.exception_info
  File "/data/data/com.termux/files/usr/lib/python3.11/site-packages/telebot/util.py", line 93, in run
    task(*args, **kwargs)
  File "/data/data/com.termux/files/usr/lib/python3.11/site-packages/telebot/__init__.py", line 676, in __retrieve_updates
    updates = self.get_updates(offset=(self.last_update_id + 1),
             ^^^^^^^^^^^^^^^^^^^^^^^^^^^^^^^^^^^^^^^^^^^^^^^^^^
  File "/data/data/com.termux/files/usr/lib/python3.11/site-packages/telebot/__init__.py", line 648, in get_updates
    json_updates = apihelper.get_updates(
                   ^^^^^^^^^^^^^^^^^^^^^^
  File "/data/data/com.termux/files/usr/lib/python3.11/site-packages/telebot/apihelper.py", line 330, in get_updates
    return _make_request(token, method_url, params=payload)
           ^^^^^^^^^^^^^^^^^^^^^^^^^^^^^^^^^^^^^^^^^^^^^^^^
  File "/data/data/com.termux/files/usr/lib/python3.11/site-packages/telebot/apihelper.py", line 168, in _make_request
    json_result = _check_result(method_name, result)
                  ^^^^^^^^^^^^^^^^^^^^^^^^^^^^^^^^^^
  File "/data/data/com.termux/files/usr/lib/python3.11/site-packages/telebot/apihelper.py", line 195, in _check_result
    raise ApiTelegramException(method_name, result, result_json)
telebot.apihelper.ApiTelegramException: A request to the Telegram API was unsuccessful. Error code: 409. Description: Conflict: terminated by other getUpdates request; make sure that only one bot instance is running

2024-08-09 11:27:25,928 - DEBUG - https://api.telegram.org:443 "GET /bot7010440554:AAGTXkaQW1wmYvvj5X2e-agZUvztY09uyng/getUpdates?offset=1&timeout=20 HTTP/11" 409 143
2024-08-09 11:27:25,930 - ERROR - Threaded polling exception: A request to the Telegram API was unsuccessful. Error code: 409. Description: Conflict: terminated by other getUpdates request; make sure that only one bot instance is running
2024-08-09 11:27:25,932 - ERROR - Exception traceback:
Traceback (most recent call last):
  File "/data/data/com.termux/files/usr/lib/python3.11/site-packages/telebot/__init__.py", line 1214, in __threaded_polling
    polling_thread.raise_exceptions()
  File "/data/data/com.termux/files/usr/lib/python3.11/site-packages/telebot/util.py", line 111, in raise_exceptions
    raise self.exception_info
  File "/data/data/com.termux/files/usr/lib/python3.11/site-packages/telebot/util.py", line 93, in run
    task(*args, **kwargs)
  File "/data/data/com.termux/files/usr/lib/python3.11/site-packages/telebot/__init__.py", line 676, in __retrieve_updates
    updates = self.get_updates(offset=(self.last_update_id + 1),
             ^^^^^^^^^^^^^^^^^^^^^^^^^^^^^^^^^^^^^^^^^^^^^^^^^^
  File "/data/data/com.termux/files/usr/lib/python3.11/site-packages/telebot/__init__.py", line 648, in get_updates
    json_updates = apihelper.get_updates(
                   ^^^^^^^^^^^^^^^^^^^^^^
  File "/data/data/com.termux/files/usr/lib/python3.11/site-packages/telebot/apihelper.py", line 330, in get_updates
    return _make_request(token, method_url, params=payload)
           ^^^^^^^^^^^^^^^^^^^^^^^^^^^^^^^^^^^^^^^^^^^^^^^^
  File "/data/data/com.termux/files/usr/lib/python3.11/site-packages/telebot/apihelper.py", line 168, in _make_request
    json_result = _check_result(method_name, result)
                  ^^^^^^^^^^^^^^^^^^^^^^^^^^^^^^^^^^
  File "/data/data/com.termux/files/usr/lib/python3.11/site-packages/telebot/apihelper.py", line 195, in _check_result
    raise ApiTelegramException(method_name, result, result_json)
telebot.apihelper.ApiTelegramException: A request to the Telegram API was unsuccessful. Error code: 409. Description: Conflict: terminated by other getUpdates request; make sure that only one bot instance is running

2024-08-09 11:27:38,325 - DEBUG - https://api.telegram.org:443 "GET /bot7010440554:AAGTXkaQW1wmYvvj5X2e-agZUvztY09uyng/getUpdates?offset=1&timeout=20 HTTP/11" 409 143
2024-08-09 11:27:38,338 - ERROR - Threaded polling exception: A request to the Telegram API was unsuccessful. Error code: 409. Description: Conflict: terminated by other getUpdates request; make sure that only one bot instance is running
2024-08-09 11:27:38,350 - ERROR - Exception traceback:
Traceback (most recent call last):
  File "/data/data/com.termux/files/usr/lib/python3.11/site-packages/telebot/__init__.py", line 1214, in __threaded_polling
    polling_thread.raise_exceptions()
  File "/data/data/com.termux/files/usr/lib/python3.11/site-packages/telebot/util.py", line 111, in raise_exceptions
    raise self.exception_info
  File "/data/data/com.termux/files/usr/lib/python3.11/site-packages/telebot/util.py", line 93, in run
    task(*args, **kwargs)
  File "/data/data/com.termux/files/usr/lib/python3.11/site-packages/telebot/__init__.py", line 676, in __retrieve_updates
    updates = self.get_updates(offset=(self.last_update_id + 1),
             ^^^^^^^^^^^^^^^^^^^^^^^^^^^^^^^^^^^^^^^^^^^^^^^^^^
  File "/data/data/com.termux/files/usr/lib/python3.11/site-packages/telebot/__init__.py", line 648, in get_updates
    json_updates = apihelper.get_updates(
                   ^^^^^^^^^^^^^^^^^^^^^^
  File "/data/data/com.termux/files/usr/lib/python3.11/site-packages/telebot/apihelper.py", line 330, in get_updates
    return _make_request(token, method_url, params=payload)
           ^^^^^^^^^^^^^^^^^^^^^^^^^^^^^^^^^^^^^^^^^^^^^^^^
  File "/data/data/com.termux/files/usr/lib/python3.11/site-packages/telebot/apihelper.py", line 168, in _make_request
    json_result = _check_result(method_name, result)
                  ^^^^^^^^^^^^^^^^^^^^^^^^^^^^^^^^^^
  File "/data/data/com.termux/files/usr/lib/python3.11/site-packages/telebot/apihelper.py", line 195, in _check_result
    raise ApiTelegramException(method_name, result, result_json)
telebot.apihelper.ApiTelegramException: A request to the Telegram API was unsuccessful. Error code: 409. Description: Conflict: terminated by other getUpdates request; make sure that only one bot instance is running

2024-08-09 11:28:02,708 - DEBUG - https://api.telegram.org:443 "GET /bot7010440554:AAGTXkaQW1wmYvvj5X2e-agZUvztY09uyng/getUpdates?offset=1&timeout=20 HTTP/11" 409 143
2024-08-09 11:28:02,713 - ERROR - Threaded polling exception: A request to the Telegram API was unsuccessful. Error code: 409. Description: Conflict: terminated by other getUpdates request; make sure that only one bot instance is running
2024-08-09 11:28:02,717 - ERROR - Exception traceback:
Traceback (most recent call last):
  File "/data/data/com.termux/files/usr/lib/python3.11/site-packages/telebot/__init__.py", line 1214, in __threaded_polling
    polling_thread.raise_exceptions()
  File "/data/data/com.termux/files/usr/lib/python3.11/site-packages/telebot/util.py", line 111, in raise_exceptions
    raise self.exception_info
  File "/data/data/com.termux/files/usr/lib/python3.11/site-packages/telebot/util.py", line 93, in run
    task(*args, **kwargs)
  File "/data/data/com.termux/files/usr/lib/python3.11/site-packages/telebot/__init__.py", line 676, in __retrieve_updates
    updates = self.get_updates(offset=(self.last_update_id + 1),
             ^^^^^^^^^^^^^^^^^^^^^^^^^^^^^^^^^^^^^^^^^^^^^^^^^^
  File "/data/data/com.termux/files/usr/lib/python3.11/site-packages/telebot/__init__.py", line 648, in get_updates
    json_updates = apihelper.get_updates(
                   ^^^^^^^^^^^^^^^^^^^^^^
  File "/data/data/com.termux/files/usr/lib/python3.11/site-packages/telebot/apihelper.py", line 330, in get_updates
    return _make_request(token, method_url, params=payload)
           ^^^^^^^^^^^^^^^^^^^^^^^^^^^^^^^^^^^^^^^^^^^^^^^^
  File "/data/data/com.termux/files/usr/lib/python3.11/site-packages/telebot/apihelper.py", line 168, in _make_request
    json_result = _check_result(method_name, result)
                  ^^^^^^^^^^^^^^^^^^^^^^^^^^^^^^^^^^
  File "/data/data/com.termux/files/usr/lib/python3.11/site-packages/telebot/apihelper.py", line 195, in _check_result
    raise ApiTelegramException(method_name, result, result_json)
telebot.apihelper.ApiTelegramException: A request to the Telegram API was unsuccessful. Error code: 409. Description: Conflict: terminated by other getUpdates request; make sure that only one bot instance is running

2024-08-09 11:28:38,905 - DEBUG - https://api.telegram.org:443 "GET /bot7010440554:AAGTXkaQW1wmYvvj5X2e-agZUvztY09uyng/getUpdates?offset=1&timeout=20 HTTP/11" 200 23
2024-08-09 11:28:51,162 - DEBUG - https://api.telegram.org:443 "GET /bot7010440554:AAGTXkaQW1wmYvvj5X2e-agZUvztY09uyng/getUpdates?offset=1&timeout=20 HTTP/11" 409 143
2024-08-09 11:28:51,195 - ERROR - Threaded polling exception: A request to the Telegram API was unsuccessful. Error code: 409. Description: Conflict: terminated by other getUpdates request; make sure that only one bot instance is running
2024-08-09 11:28:51,217 - ERROR - Exception traceback:
Traceback (most recent call last):
  File "/data/data/com.termux/files/usr/lib/python3.11/site-packages/telebot/__init__.py", line 1214, in __threaded_polling
    polling_thread.raise_exceptions()
  File "/data/data/com.termux/files/usr/lib/python3.11/site-packages/telebot/util.py", line 111, in raise_exceptions
    raise self.exception_info
  File "/data/data/com.termux/files/usr/lib/python3.11/site-packages/telebot/util.py", line 93, in run
    task(*args, **kwargs)
  File "/data/data/com.termux/files/usr/lib/python3.11/site-packages/telebot/__init__.py", line 676, in __retrieve_updates
    updates = self.get_updates(offset=(self.last_update_id + 1),
             ^^^^^^^^^^^^^^^^^^^^^^^^^^^^^^^^^^^^^^^^^^^^^^^^^^
  File "/data/data/com.termux/files/usr/lib/python3.11/site-packages/telebot/__init__.py", line 648, in get_updates
    json_updates = apihelper.get_updates(
                   ^^^^^^^^^^^^^^^^^^^^^^
  File "/data/data/com.termux/files/usr/lib/python3.11/site-packages/telebot/apihelper.py", line 330, in get_updates
    return _make_request(token, method_url, params=payload)
           ^^^^^^^^^^^^^^^^^^^^^^^^^^^^^^^^^^^^^^^^^^^^^^^^
  File "/data/data/com.termux/files/usr/lib/python3.11/site-packages/telebot/apihelper.py", line 168, in _make_request
    json_result = _check_result(method_name, result)
                  ^^^^^^^^^^^^^^^^^^^^^^^^^^^^^^^^^^
  File "/data/data/com.termux/files/usr/lib/python3.11/site-packages/telebot/apihelper.py", line 195, in _check_result
    raise ApiTelegramException(method_name, result, result_json)
telebot.apihelper.ApiTelegramException: A request to the Telegram API was unsuccessful. Error code: 409. Description: Conflict: terminated by other getUpdates request; make sure that only one bot instance is running

2024-08-09 11:29:11,824 - DEBUG - https://api.telegram.org:443 "GET /bot7010440554:AAGTXkaQW1wmYvvj5X2e-agZUvztY09uyng/getUpdates?offset=1&timeout=20 HTTP/11" 200 23
2024-08-09 11:29:32,018 - DEBUG - https://api.telegram.org:443 "GET /bot7010440554:AAGTXkaQW1wmYvvj5X2e-agZUvztY09uyng/getUpdates?offset=1&timeout=20 HTTP/11" 200 23
2024-08-09 11:29:52,259 - DEBUG - https://api.telegram.org:443 "GET /bot7010440554:AAGTXkaQW1wmYvvj5X2e-agZUvztY09uyng/getUpdates?offset=1&timeout=20 HTTP/11" 200 23
2024-08-09 11:29:54,888 - DEBUG - https://api.telegram.org:443 "GET /bot7010440554:AAGTXkaQW1wmYvvj5X2e-agZUvztY09uyng/getUpdates?offset=1&timeout=20 HTTP/11" 409 143
2024-08-09 11:29:54,894 - ERROR - Threaded polling exception: A request to the Telegram API was unsuccessful. Error code: 409. Description: Conflict: terminated by other getUpdates request; make sure that only one bot instance is running
2024-08-09 11:29:54,900 - ERROR - Exception traceback:
Traceback (most recent call last):
  File "/data/data/com.termux/files/usr/lib/python3.11/site-packages/telebot/__init__.py", line 1214, in __threaded_polling
    polling_thread.raise_exceptions()
  File "/data/data/com.termux/files/usr/lib/python3.11/site-packages/telebot/util.py", line 111, in raise_exceptions
    raise self.exception_info
  File "/data/data/com.termux/files/usr/lib/python3.11/site-packages/telebot/util.py", line 93, in run
    task(*args, **kwargs)
  File "/data/data/com.termux/files/usr/lib/python3.11/site-packages/telebot/__init__.py", line 676, in __retrieve_updates
    updates = self.get_updates(offset=(self.last_update_id + 1),
             ^^^^^^^^^^^^^^^^^^^^^^^^^^^^^^^^^^^^^^^^^^^^^^^^^^
  File "/data/data/com.termux/files/usr/lib/python3.11/site-packages/telebot/__init__.py", line 648, in get_updates
    json_updates = apihelper.get_updates(
                   ^^^^^^^^^^^^^^^^^^^^^^
  File "/data/data/com.termux/files/usr/lib/python3.11/site-packages/telebot/apihelper.py", line 330, in get_updates
    return _make_request(token, method_url, params=payload)
           ^^^^^^^^^^^^^^^^^^^^^^^^^^^^^^^^^^^^^^^^^^^^^^^^
  File "/data/data/com.termux/files/usr/lib/python3.11/site-packages/telebot/apihelper.py", line 168, in _make_request
    json_result = _check_result(method_name, result)
                  ^^^^^^^^^^^^^^^^^^^^^^^^^^^^^^^^^^
  File "/data/data/com.termux/files/usr/lib/python3.11/site-packages/telebot/apihelper.py", line 195, in _check_result
    raise ApiTelegramException(method_name, result, result_json)
telebot.apihelper.ApiTelegramException: A request to the Telegram API was unsuccessful. Error code: 409. Description: Conflict: terminated by other getUpdates request; make sure that only one bot instance is running

2024-08-09 11:30:15,335 - DEBUG - https://api.telegram.org:443 "GET /bot7010440554:AAGTXkaQW1wmYvvj5X2e-agZUvztY09uyng/getUpdates?offset=1&timeout=20 HTTP/11" 200 23
2024-08-09 11:30:35,593 - DEBUG - https://api.telegram.org:443 "GET /bot7010440554:AAGTXkaQW1wmYvvj5X2e-agZUvztY09uyng/getUpdates?offset=1&timeout=20 HTTP/11" 200 23
2024-08-09 11:30:55,831 - DEBUG - https://api.telegram.org:443 "GET /bot7010440554:AAGTXkaQW1wmYvvj5X2e-agZUvztY09uyng/getUpdates?offset=1&timeout=20 HTTP/11" 200 23
2024-08-09 11:30:58,535 - DEBUG - https://api.telegram.org:443 "GET /bot7010440554:AAGTXkaQW1wmYvvj5X2e-agZUvztY09uyng/getUpdates?offset=1&timeout=20 HTTP/11" 409 143
2024-08-09 11:30:58,541 - ERROR - Threaded polling exception: A request to the Telegram API was unsuccessful. Error code: 409. Description: Conflict: terminated by other getUpdates request; make sure that only one bot instance is running
2024-08-09 11:30:58,550 - ERROR - Exception traceback:
Traceback (most recent call last):
  File "/data/data/com.termux/files/usr/lib/python3.11/site-packages/telebot/__init__.py", line 1214, in __threaded_polling
    polling_thread.raise_exceptions()
  File "/data/data/com.termux/files/usr/lib/python3.11/site-packages/telebot/util.py", line 111, in raise_exceptions
    raise self.exception_info
  File "/data/data/com.termux/files/usr/lib/python3.11/site-packages/telebot/util.py", line 93, in run
    task(*args, **kwargs)
  File "/data/data/com.termux/files/usr/lib/python3.11/site-packages/telebot/__init__.py", line 676, in __retrieve_updates
    updates = self.get_updates(offset=(self.last_update_id + 1),
             ^^^^^^^^^^^^^^^^^^^^^^^^^^^^^^^^^^^^^^^^^^^^^^^^^^
  File "/data/data/com.termux/files/usr/lib/python3.11/site-packages/telebot/__init__.py", line 648, in get_updates
    json_updates = apihelper.get_updates(
                   ^^^^^^^^^^^^^^^^^^^^^^
  File "/data/data/com.termux/files/usr/lib/python3.11/site-packages/telebot/apihelper.py", line 330, in get_updates
    return _make_request(token, method_url, params=payload)
           ^^^^^^^^^^^^^^^^^^^^^^^^^^^^^^^^^^^^^^^^^^^^^^^^
  File "/data/data/com.termux/files/usr/lib/python3.11/site-packages/telebot/apihelper.py", line 168, in _make_request
    json_result = _check_result(method_name, result)
                  ^^^^^^^^^^^^^^^^^^^^^^^^^^^^^^^^^^
  File "/data/data/com.termux/files/usr/lib/python3.11/site-packages/telebot/apihelper.py", line 195, in _check_result
    raise ApiTelegramException(method_name, result, result_json)
telebot.apihelper.ApiTelegramException: A request to the Telegram API was unsuccessful. Error code: 409. Description: Conflict: terminated by other getUpdates request; make sure that only one bot instance is running

2024-08-09 11:31:18,988 - DEBUG - https://api.telegram.org:443 "GET /bot7010440554:AAGTXkaQW1wmYvvj5X2e-agZUvztY09uyng/getUpdates?offset=1&timeout=20 HTTP/11" 200 23
2024-08-09 11:31:39,182 - DEBUG - https://api.telegram.org:443 "GET /bot7010440554:AAGTXkaQW1wmYvvj5X2e-agZUvztY09uyng/getUpdates?offset=1&timeout=20 HTTP/11" 200 23
2024-08-09 11:31:59,380 - DEBUG - https://api.telegram.org:443 "GET /bot7010440554:AAGTXkaQW1wmYvvj5X2e-agZUvztY09uyng/getUpdates?offset=1&timeout=20 HTTP/11" 200 23
2024-08-09 11:32:02,176 - DEBUG - https://api.telegram.org:443 "GET /bot7010440554:AAGTXkaQW1wmYvvj5X2e-agZUvztY09uyng/getUpdates?offset=1&timeout=20 HTTP/11" 409 143
2024-08-09 11:32:02,190 - ERROR - Threaded polling exception: A request to the Telegram API was unsuccessful. Error code: 409. Description: Conflict: terminated by other getUpdates request; make sure that only one bot instance is running
2024-08-09 11:32:02,200 - ERROR - Exception traceback:
Traceback (most recent call last):
  File "/data/data/com.termux/files/usr/lib/python3.11/site-packages/telebot/__init__.py", line 1214, in __threaded_polling
    polling_thread.raise_exceptions()
  File "/data/data/com.termux/files/usr/lib/python3.11/site-packages/telebot/util.py", line 111, in raise_exceptions
    raise self.exception_info
  File "/data/data/com.termux/files/usr/lib/python3.11/site-packages/telebot/util.py", line 93, in run
    task(*args, **kwargs)
  File "/data/data/com.termux/files/usr/lib/python3.11/site-packages/telebot/__init__.py", line 676, in __retrieve_updates
    updates = self.get_updates(offset=(self.last_update_id + 1),
             ^^^^^^^^^^^^^^^^^^^^^^^^^^^^^^^^^^^^^^^^^^^^^^^^^^
  File "/data/data/com.termux/files/usr/lib/python3.11/site-packages/telebot/__init__.py", line 648, in get_updates
    json_updates = apihelper.get_updates(
                   ^^^^^^^^^^^^^^^^^^^^^^
  File "/data/data/com.termux/files/usr/lib/python3.11/site-packages/telebot/apihelper.py", line 330, in get_updates
    return _make_request(token, method_url, params=payload)
           ^^^^^^^^^^^^^^^^^^^^^^^^^^^^^^^^^^^^^^^^^^^^^^^^
  File "/data/data/com.termux/files/usr/lib/python3.11/site-packages/telebot/apihelper.py", line 168, in _make_request
    json_result = _check_result(method_name, result)
                  ^^^^^^^^^^^^^^^^^^^^^^^^^^^^^^^^^^
  File "/data/data/com.termux/files/usr/lib/python3.11/site-packages/telebot/apihelper.py", line 195, in _check_result
    raise ApiTelegramException(method_name, result, result_json)
telebot.apihelper.ApiTelegramException: A request to the Telegram API was unsuccessful. Error code: 409. Description: Conflict: terminated by other getUpdates request; make sure that only one bot instance is running

2024-08-09 11:32:22,651 - DEBUG - https://api.telegram.org:443 "GET /bot7010440554:AAGTXkaQW1wmYvvj5X2e-agZUvztY09uyng/getUpdates?offset=1&timeout=20 HTTP/11" 200 23
2024-08-09 11:32:43,271 - DEBUG - https://api.telegram.org:443 "GET /bot7010440554:AAGTXkaQW1wmYvvj5X2e-agZUvztY09uyng/getUpdates?offset=1&timeout=20 HTTP/11" 200 23
2024-08-09 11:33:03,490 - DEBUG - https://api.telegram.org:443 "GET /bot7010440554:AAGTXkaQW1wmYvvj5X2e-agZUvztY09uyng/getUpdates?offset=1&timeout=20 HTTP/11" 200 23
2024-08-09 11:33:05,992 - DEBUG - https://api.telegram.org:443 "GET /bot7010440554:AAGTXkaQW1wmYvvj5X2e-agZUvztY09uyng/getUpdates?offset=1&timeout=20 HTTP/11" 409 143
2024-08-09 11:33:06,004 - ERROR - Threaded polling exception: A request to the Telegram API was unsuccessful. Error code: 409. Description: Conflict: terminated by other getUpdates request; make sure that only one bot instance is running
2024-08-09 11:33:06,131 - ERROR - Exception traceback:
Traceback (most recent call last):
  File "/data/data/com.termux/files/usr/lib/python3.11/site-packages/telebot/__init__.py", line 1214, in __threaded_polling
    polling_thread.raise_exceptions()
  File "/data/data/com.termux/files/usr/lib/python3.11/site-packages/telebot/util.py", line 111, in raise_exceptions
    raise self.exception_info
  File "/data/data/com.termux/files/usr/lib/python3.11/site-packages/telebot/util.py", line 93, in run
    task(*args, **kwargs)
  File "/data/data/com.termux/files/usr/lib/python3.11/site-packages/telebot/__init__.py", line 676, in __retrieve_updates
    updates = self.get_updates(offset=(self.last_update_id + 1),
             ^^^^^^^^^^^^^^^^^^^^^^^^^^^^^^^^^^^^^^^^^^^^^^^^^^
  File "/data/data/com.termux/files/usr/lib/python3.11/site-packages/telebot/__init__.py", line 648, in get_updates
    json_updates = apihelper.get_updates(
                   ^^^^^^^^^^^^^^^^^^^^^^
  File "/data/data/com.termux/files/usr/lib/python3.11/site-packages/telebot/apihelper.py", line 330, in get_updates
    return _make_request(token, method_url, params=payload)
           ^^^^^^^^^^^^^^^^^^^^^^^^^^^^^^^^^^^^^^^^^^^^^^^^
  File "/data/data/com.termux/files/usr/lib/python3.11/site-packages/telebot/apihelper.py", line 168, in _make_request
    json_result = _check_result(method_name, result)
                  ^^^^^^^^^^^^^^^^^^^^^^^^^^^^^^^^^^
  File "/data/data/com.termux/files/usr/lib/python3.11/site-packages/telebot/apihelper.py", line 195, in _check_result
    raise ApiTelegramException(method_name, result, result_json)
telebot.apihelper.ApiTelegramException: A request to the Telegram API was unsuccessful. Error code: 409. Description: Conflict: terminated by other getUpdates request; make sure that only one bot instance is running

2024-08-09 11:33:26,590 - DEBUG - https://api.telegram.org:443 "GET /bot7010440554:AAGTXkaQW1wmYvvj5X2e-agZUvztY09uyng/getUpdates?offset=1&timeout=20 HTTP/11" 200 23
2024-08-09 11:33:46,796 - DEBUG - https://api.telegram.org:443 "GET /bot7010440554:AAGTXkaQW1wmYvvj5X2e-agZUvztY09uyng/getUpdates?offset=1&timeout=20 HTTP/11" 200 23
2024-08-09 11:34:07,351 - DEBUG - https://api.telegram.org:443 "GET /bot7010440554:AAGTXkaQW1wmYvvj5X2e-agZUvztY09uyng/getUpdates?offset=1&timeout=20 HTTP/11" 200 23
2024-08-09 11:34:10,455 - DEBUG - https://api.telegram.org:443 "GET /bot7010440554:AAGTXkaQW1wmYvvj5X2e-agZUvztY09uyng/getUpdates?offset=1&timeout=20 HTTP/11" 409 143
2024-08-09 11:34:10,470 - ERROR - Threaded polling exception: A request to the Telegram API was unsuccessful. Error code: 409. Description: Conflict: terminated by other getUpdates request; make sure that only one bot instance is running
2024-08-09 11:34:10,484 - ERROR - Exception traceback:
Traceback (most recent call last):
  File "/data/data/com.termux/files/usr/lib/python3.11/site-packages/telebot/__init__.py", line 1214, in __threaded_polling
    polling_thread.raise_exceptions()
  File "/data/data/com.termux/files/usr/lib/python3.11/site-packages/telebot/util.py", line 111, in raise_exceptions
    raise self.exception_info
  File "/data/data/com.termux/files/usr/lib/python3.11/site-packages/telebot/util.py", line 93, in run
    task(*args, **kwargs)
  File "/data/data/com.termux/files/usr/lib/python3.11/site-packages/telebot/__init__.py", line 676, in __retrieve_updates
    updates = self.get_updates(offset=(self.last_update_id + 1),
             ^^^^^^^^^^^^^^^^^^^^^^^^^^^^^^^^^^^^^^^^^^^^^^^^^^
  File "/data/data/com.termux/files/usr/lib/python3.11/site-packages/telebot/__init__.py", line 648, in get_updates
    json_updates = apihelper.get_updates(
                   ^^^^^^^^^^^^^^^^^^^^^^
  File "/data/data/com.termux/files/usr/lib/python3.11/site-packages/telebot/apihelper.py", line 330, in get_updates
    return _make_request(token, method_url, params=payload)
           ^^^^^^^^^^^^^^^^^^^^^^^^^^^^^^^^^^^^^^^^^^^^^^^^
  File "/data/data/com.termux/files/usr/lib/python3.11/site-packages/telebot/apihelper.py", line 168, in _make_request
    json_result = _check_result(method_name, result)
                  ^^^^^^^^^^^^^^^^^^^^^^^^^^^^^^^^^^
  File "/data/data/com.termux/files/usr/lib/python3.11/site-packages/telebot/apihelper.py", line 195, in _check_result
    raise ApiTelegramException(method_name, result, result_json)
telebot.apihelper.ApiTelegramException: A request to the Telegram API was unsuccessful. Error code: 409. Description: Conflict: terminated by other getUpdates request; make sure that only one bot instance is running

2024-08-09 11:34:30,925 - DEBUG - https://api.telegram.org:443 "GET /bot7010440554:AAGTXkaQW1wmYvvj5X2e-agZUvztY09uyng/getUpdates?offset=1&timeout=20 HTTP/11" 200 23
2024-08-09 11:34:51,183 - DEBUG - https://api.telegram.org:443 "GET /bot7010440554:AAGTXkaQW1wmYvvj5X2e-agZUvztY09uyng/getUpdates?offset=1&timeout=20 HTTP/11" 200 23
2024-08-09 11:35:11,393 - DEBUG - https://api.telegram.org:443 "GET /bot7010440554:AAGTXkaQW1wmYvvj5X2e-agZUvztY09uyng/getUpdates?offset=1&timeout=20 HTTP/11" 200 23
2024-08-09 11:35:14,203 - DEBUG - https://api.telegram.org:443 "GET /bot7010440554:AAGTXkaQW1wmYvvj5X2e-agZUvztY09uyng/getUpdates?offset=1&timeout=20 HTTP/11" 409 143
2024-08-09 11:35:14,216 - ERROR - Threaded polling exception: A request to the Telegram API was unsuccessful. Error code: 409. Description: Conflict: terminated by other getUpdates request; make sure that only one bot instance is running
2024-08-09 11:35:14,229 - ERROR - Exception traceback:
Traceback (most recent call last):
  File "/data/data/com.termux/files/usr/lib/python3.11/site-packages/telebot/__init__.py", line 1214, in __threaded_polling
    polling_thread.raise_exceptions()
  File "/data/data/com.termux/files/usr/lib/python3.11/site-packages/telebot/util.py", line 111, in raise_exceptions
    raise self.exception_info
  File "/data/data/com.termux/files/usr/lib/python3.11/site-packages/telebot/util.py", line 93, in run
    task(*args, **kwargs)
  File "/data/data/com.termux/files/usr/lib/python3.11/site-packages/telebot/__init__.py", line 676, in __retrieve_updates
    updates = self.get_updates(offset=(self.last_update_id + 1),
             ^^^^^^^^^^^^^^^^^^^^^^^^^^^^^^^^^^^^^^^^^^^^^^^^^^
  File "/data/data/com.termux/files/usr/lib/python3.11/site-packages/telebot/__init__.py", line 648, in get_updates
    json_updates = apihelper.get_updates(
                   ^^^^^^^^^^^^^^^^^^^^^^
  File "/data/data/com.termux/files/usr/lib/python3.11/site-packages/telebot/apihelper.py", line 330, in get_updates
    return _make_request(token, method_url, params=payload)
           ^^^^^^^^^^^^^^^^^^^^^^^^^^^^^^^^^^^^^^^^^^^^^^^^
  File "/data/data/com.termux/files/usr/lib/python3.11/site-packages/telebot/apihelper.py", line 168, in _make_request
    json_result = _check_result(method_name, result)
                  ^^^^^^^^^^^^^^^^^^^^^^^^^^^^^^^^^^
  File "/data/data/com.termux/files/usr/lib/python3.11/site-packages/telebot/apihelper.py", line 195, in _check_result
    raise ApiTelegramException(method_name, result, result_json)
telebot.apihelper.ApiTelegramException: A request to the Telegram API was unsuccessful. Error code: 409. Description: Conflict: terminated by other getUpdates request; make sure that only one bot instance is running

2024-08-09 11:35:34,679 - DEBUG - https://api.telegram.org:443 "GET /bot7010440554:AAGTXkaQW1wmYvvj5X2e-agZUvztY09uyng/getUpdates?offset=1&timeout=20 HTTP/11" 200 23
2024-08-09 11:35:54,898 - DEBUG - https://api.telegram.org:443 "GET /bot7010440554:AAGTXkaQW1wmYvvj5X2e-agZUvztY09uyng/getUpdates?offset=1&timeout=20 HTTP/11" 200 23
2024-08-09 11:36:15,086 - DEBUG - https://api.telegram.org:443 "GET /bot7010440554:AAGTXkaQW1wmYvvj5X2e-agZUvztY09uyng/getUpdates?offset=1&timeout=20 HTTP/11" 200 23
2024-08-09 11:36:18,524 - DEBUG - https://api.telegram.org:443 "GET /bot7010440554:AAGTXkaQW1wmYvvj5X2e-agZUvztY09uyng/getUpdates?offset=1&timeout=20 HTTP/11" 409 143
2024-08-09 11:36:18,526 - ERROR - Threaded polling exception: A request to the Telegram API was unsuccessful. Error code: 409. Description: Conflict: terminated by other getUpdates request; make sure that only one bot instance is running
2024-08-09 11:36:18,536 - ERROR - Exception traceback:
Traceback (most recent call last):
  File "/data/data/com.termux/files/usr/lib/python3.11/site-packages/telebot/__init__.py", line 1214, in __threaded_polling
    polling_thread.raise_exceptions()
  File "/data/data/com.termux/files/usr/lib/python3.11/site-packages/telebot/util.py", line 111, in raise_exceptions
    raise self.exception_info
  File "/data/data/com.termux/files/usr/lib/python3.11/site-packages/telebot/util.py", line 93, in run
    task(*args, **kwargs)
  File "/data/data/com.termux/files/usr/lib/python3.11/site-packages/telebot/__init__.py", line 676, in __retrieve_updates
    updates = self.get_updates(offset=(self.last_update_id + 1),
             ^^^^^^^^^^^^^^^^^^^^^^^^^^^^^^^^^^^^^^^^^^^^^^^^^^
  File "/data/data/com.termux/files/usr/lib/python3.11/site-packages/telebot/__init__.py", line 648, in get_updates
    json_updates = apihelper.get_updates(
                   ^^^^^^^^^^^^^^^^^^^^^^
  File "/data/data/com.termux/files/usr/lib/python3.11/site-packages/telebot/apihelper.py", line 330, in get_updates
    return _make_request(token, method_url, params=payload)
           ^^^^^^^^^^^^^^^^^^^^^^^^^^^^^^^^^^^^^^^^^^^^^^^^
  File "/data/data/com.termux/files/usr/lib/python3.11/site-packages/telebot/apihelper.py", line 168, in _make_request
    json_result = _check_result(method_name, result)
                  ^^^^^^^^^^^^^^^^^^^^^^^^^^^^^^^^^^
  File "/data/data/com.termux/files/usr/lib/python3.11/site-packages/telebot/apihelper.py", line 195, in _check_result
    raise ApiTelegramException(method_name, result, result_json)
telebot.apihelper.ApiTelegramException: A request to the Telegram API was unsuccessful. Error code: 409. Description: Conflict: terminated by other getUpdates request; make sure that only one bot instance is running

2024-08-09 11:36:39,078 - DEBUG - https://api.telegram.org:443 "GET /bot7010440554:AAGTXkaQW1wmYvvj5X2e-agZUvztY09uyng/getUpdates?offset=1&timeout=20 HTTP/11" 200 23
